Workbook

Sheet Contact Tracker
A1: HR Leader Contact Tracker
A2: Meeting Date | B2: Meeting Status | C2: Meeting Type | D2: Contact ID | E2: Name of Contact | F2: Designation | G2: Company Name | H2: Industry | I2: Location | J2: Contact Source | K2: Email | L2: Phone Number | M2: LinkedIn Profile | N2: Meeting Summary | O2: Detailed MOM (Ref/Link) | P2: Key Pain Points Identified | Q2: Opportunities Identified | R2: Interest Level | S2: Relationship Status | T2: Next Follow-up Date | U2: Follow-up Status | V2: Date of First Contact | W2: Last Interaction Date | X2: Remarks
A3: 46079 | B3: Completed | C3: Online | D3: CHR-001 | E3: Swati Joshi | F3: HR Recruiter / HR Professional | G3: Brand Connections | H3: HR / Recruitment | I3: Ahmedabad | J3: Vivek Dagur | M3: https://www.linkedin.com/in/joshi-swati/ | R3: High | S3: New | T3: 46162 | U3: Pending
A4: 46083 | B4: Completed | C4: Online | D4: CHR-002 | E4: Archit Patel | F4: CHRO and Head | G4: Meghmani LLP | H4: Pharma | I4: Ahmedabad | J4: EDII | K4: Archit.dhara.patel@gmail.com | L4: 9662520345 | M4: linkedin.com/in/archit-b-patel | Q4: Bucket B | R4: Medium | S4: New | T4: 46158 | U4: Pending | V4: 46083 | W4: 46083 | X4: EDII
A5: 46083 | B5: Completed | C5: Online | D5: CHR-003 | E5: Amit Gadhvi | F5: CHRO and Head | G5: Unknown | H5: Pharma and tech | I5: Ahmedabad | J5: Archit Patel | K5: gadhavi.amit@gmail.com | L5: Unknown | M5: Unknown | Q5: Bucket B | R5: Medium | S5: New | T5: 46159 | U5: Pending | V5: 46083 | W5: 46083 | X5: EDII
A6: 46128 | B6: Completed | C6: In-person | D6: CHR-004 | E6: Leena Lopez | F6: Vice President – Strategy & Human Resources | G6: Knowcraft Analytics | H6: Analytics / Data | I6: Ahmedabad | J6: Referral (Furkan Sir) | K6: Unknown | L6: +91 9712972477 | M6: https://www.linkedin.com/in/leenaantony/ | Q6: Bucket C | R6: Medium | S6: New | T6: 46157 | U6: Done | V6: 46128 | W6: 46147 | X6: Referred by Furkan Sir
A7: 46149 | B7: Completed | C7: In-person | D7: CHR-005 | E7: Kunal Naik | F7: Director | G7: Managing Director at Technomine group | I7: Ahmedabad | J7: Referral (Rohan Shah) | K7: Unknown | L7: +91 9925149599 | M7: https://www.linkedin.com/in/kunal-mehta-9071911/ | Q7: Bucket B/C | R7: High | S7: New | T7: 46157 | U7: Pending | V7: 46146 | W7: 46146 | X7: Referred by Rohan Shah
A8: 46149 | B8: Completed | C8: In-person | D8: CHR-006 | E8: Hemang Desai | F8: CHRO | G8: Ishan Technologies | H8: IT / Telecom / Networking | I8: Gandhinagar | J8: EDII | K8: Unknown | L8: 9909930880 | M8: https://www.linkedin.com/in/hemang-desai-for-organisational-transformation/ | Q8: Bucket A | R8: High | S8: New | T8: JUNE | U8: Pending | V8: 46138 | W8: 46147 | X8: EDII
A9: 46150 | B9: Completed | C9: In-person | D9: CHR-007 | E9: Mitali Saxena | F9: HR Manager – Factory HR | G9: CET Enviro – Cooling Efficiency Technologies | H9: Manufacturing / Engineering | I9: Ahmedabad | J9: Anurag Dagur | L9: 9033042978 | M9: https://www.linkedin.com/in/meetali-saxena-13624b55/ | Q9: Bucket B or testing | R9: High | S9: New | T9: 46162 | U9: Pending | V9: 46150 | W9: 46150
A10: 46153 | B10: Completed | C10: In-person | D10: CHR-008 | E10: Rushad Shah | F10: AVP HR | G10: Cygnet.one | H10: Software development | I10: Ahmedabad | J10: Referral (Leena Lopez) | K10: Unknown | L10: +91 9099048431 | M10: linkedin.com/in/rushad-shah-b8584114 | Q10: Bucket B | R10: High | S10: New | T10: 46157 | U10: Pending | V10: 46146 | W10: 46146 | X10: Referred by Leena Lopez
A11: 46153 | B11: Completed | C11: In-person | D11: CHR-009 | E11: Darshit Thakkar | I11: Ahmedabad | J11: Pravin bhai | L11: 8238053156 | Q11: Bucket B | V11: 46153 | W11: 46153
A12: 46154 | B12: Completed | C12: Zoom | D12: CHR-010 | E12: Jay Thakker | F12: HR Leader | G12: A.P. Moller - Maersk | H12: Shipping / Logistics | I12: Singapore | J12: Vivek Dagur | K12: thakerjay@hotmail.com | L12: 9821509243 | M12: linkedin.com/in/jay-thaker-8b209611 | Q12: Bucket A/B | T12: JUNE | V12: 46154 | W12: 46154
A13: 46154 | B13: Completed | C13: Online | D13: CHR-011 | E13: Preksha Pandhya | F13: HR & OD Consultant / CEO | G13: Kartavya HR Consultants | H13: HR Consulting / OD | I13: Vadodara | J13: Pravin bhai | L13: 7203814141 | M13: linkedin.com/in/preksha-pandya | Q13: Bucket B | V13: 46154 | W13: 46154
A14: 46155 | B14: Completed | C14: In-person | D14: CHR-012 | E14: Prof Harshmita | G14: EDII – Entrepreneurship Development Institute of India | H14: Education / Academia | I14: Ahmedabad | J14: Rohit Swaroop | Q14: Bucket C | V14: 46155 | W14: 46155
A15: 46155 | B15: Completed | C15: In-person | D15: CHR-013 | E15: Bharat Kishnani | F15: CHRO and Head | G15: Adani Group | H15: Conglomerate / Infrastructure | I15: Ahmedabad | J15: Hemang Desai | L15: 7777966099 | M15: linkedin.com/in/bharat-kishnani-210a5150 | Q15: Bucket B | V15: 46155 | W15: 46155
A16: 46155 | B16: Completed | C16: In-person | D16: CHR-014 | E16: Rohit Swarup | F16: Founder & MD | G16: Designversity & Explorra Education Pvt Ltd | H16: Education / EdTech | I16: Ahmedabad | J16: EDII | L16: 9327521343 | M16: linkedin.com/in/rohit-swarup-xdsindia | Q16: Bucket B or testing | V16: 46155 | W16: 46155
A17: 46156 | B17: Completed | C17: online | D17: CHR-015 | E17: Richa Patel | F17: Circle Head HR | G17: Indus Towers | H17: Telecom Infrastructure | I17: Ahmedabad | J17: Sanjay Rao | L17: 9619964799 | M17: linkedin.com/in/richa-patel-83b8921a | Q17: Bucket A | T17: JUNE | U17: Done | V17: 46155 | W17: 46156
A18: 46157 | B18: Completed | C18: online | D18: CHR-016 | E18: Jenny Benoy | F18: AVP - HR | G18: Etech India | H18: IT / BPO | I18: Gandhinagar | J18: Hemang Desai | L18: 9099330001 | M18: linkedin.com/in/jennybenoy | Q18: Bucket B | V18: 46157 | W18: 46157
A19: 46157 | B19: Completed | C19: In person | D19: CHR-017 | E19: Sarika Bhatt | F19: Strategic HR professional | G19: Novasol Ingredients Pvt. Ltd | H19: Specialty Chemicals / Manufacturing | I19: Ahmedabad | J19: Hemang Desai | L19: 7433011177 | M19: linkedin.com/in/sarika-bhatt-78170b22 | Q19: Bucket B | V19: 46157 | W19: 46157
A20: 46158 | B20: Completed | C20: In-person | D20: CHR-018 | E20: Chainsingh Rathod | F20: Vice President - Talent Acquisition & Operations- Hiring Top Talent Across the Globe | G20: Gateway Group of Companies | H20: Diversified / Conglomerate | I20: Ahmedabad | J20: Rushad Shah | L20: 9879610119 | M20: linkedin.com/in/chainsingh-rathore-56676035 | Q20: Bucket B | U20: Done | V20: 46154 | W20: 46158
A21: ▼ NOT YET MET
D22: CHR-019 | E22: Dr. Parag Bhatt | F22: CHRO and Head | G22: Zydus hospitals | H22: Pharma | I22: Ahmedabad | J22: Referral (Rohan Shah) | K22: Unknown | L22: +91 7506034440 | M22: https://www.linkedin.com/in/paragbhatt/ | R22: High | S22: New | T22: 46157 | U22: Pending | V22: 46146 | W22: 46146 | X22: Referred by Rohan Shah
D23: CHR-020 | E23: Garima Sharma | K23: sharmagarima03@gmail.com | M23: https://www.linkedin.com/in/hetakshi-shah-672711171/ | V23: 46147 | W23: 46147
D24: CHR-021 | E24: Hetakshi | F24: HR Junior Executive | G24: Torrent Power Limited | H24: Power / Energy / Utilities | I24: Ahmedabad | M24: linkedin.com/in/hetakshi-shah-672711171 | V24: 46147 | W24: 46147
D25: CHR-022 | E25: Jeel | I25: Ahmedabad | J25: Hardi | M25: linkedin.com/in/jeel-bosamiya-105252130 | V25: 46147 | W25: 46147
D26: CHR-023 | E26: Ashok | I26: Ahmedabad | R26: High | S26: New | T26: 46162 | U26: Pending | V26: 46148 | W26: 46148
D27: CHR-024 | E27: Iota | I27: Ahmedabad | R27: High | S27: New | T27: 46162 | U27: Pending | V27: 46148 | W27: 46148
D28: CHR-025 | E28: Furkan | I28: Ahmedabad | J28: EDII | R28: High | S28: New | T28: 46162 | U28: Pending | V28: 46148 | W28: 46148
D29: CHR-026 | E29: Sarika | I29: Ahmedabad | J29: EDII | R29: High | S29: New | T29: 46162 | U29: Pending | V29: 46148 | W29: 46148
D30: CHR-027 | E30: Priti Bhame | I30: Pune | J30: Vivek Dagur | R30: High | S30: New | T30: 46162 | U30: Pending | V30: 46148 | W30: 46148
D31: CHR-028 | E31: Anant Panchal | J31: Archit Patel | K31: panchal.anant1@gmail.com | V31: 46083 | W31: 46083
B32: Not Set | D32: CHR-029 | E32: Dhara Shah | F32: CHRO and Head | G32: Deloitte | H32: Professional Services / Consulting | I32: Mumbai | J32: Hemang Desai | L32: 9724488788 | M32: linkedin.com/in/dhararshah | V32: 46151 | W32: 46151
D33: CHR-030 | E33: Alpa Bhatt | F33: CHRO and Head | G33: Ishan Technologies | H33: IT / Telecom | I33: Ahmedabad | J33: Hemang Desai | L33: 9824003101 | M33: linkedin.com/in/alpa-bhatt | W33: None
D34: CHR-031 | E34: Anuja Kochhar | F34: CHRO and Head | J34: Hemang Desai | L34: 9099070977 | M34: linkedin.com/in/anuja-rishi-kochhar-69a079b7 | W34: None
D35: CHR-032 | E35: Deepti Arora | F35: CHRO and Head | J35: Hemang Desai | L35: 9924144097 | M35: linkedin.com/in/deepti-arora-79568a3 | W35: None
D36: CHR-033 | E36: Devang pandya | F36: CHRO and Head | J36: Hemang Desai | L36: 9227917886 | M36: linkedin.com/in/devangpandya | Q36: Bucket A | T36: JUNE | W36: None
D37: CHR-034 | E37: Viral Mankodi | F37: CHRO and Head | J37: Hemang Desai | K37: viral.mankodi@hotmail.com | L37: 9824050761 | M37: linkedin.com/in/viral-mankodi-6642a06 | W37: None
D38: CHR-035 | E38: Vishwas Vora | F38: Strategic HR professional | J38: Hemang Desai | L38: 9879200585 | M38: linkedin.com/in/vishwas-vora-2387b42 | W38: None
D39: CHR-036 | E39: Mohit Gupta | I39: Ahmedabad | J39: Rushad Shah | L39: 9825152029 | V39: 46154 | W39: 46154
D40: CHR-037 | E40: Rahul Pandey | I40: Ahmedabad | J40: Krishnan Mishra | L40: 9819764433
...

Sheet Network Bridge
A1: Network Bridge – Connectors for HR Contact Discovery
A2: People in our network who can refer / share contact details of target HRs — e.g., Anurag Dagur and similar connectors
A3: Net ID | B3: Connector Name | C3: Designation | D3: Company | E3: Our Relationship | F3: Target HR to Reach | G3: Target Company | H3: Outreach Method | I3: Date of Outreach | J3: Response Status | K3: HR Contact Received? | L3: HR Email / Phone Obtained | M3: Remarks / Notes
A4: NTW-001 | B4: Anurag Dagur | C4: HR Consultant / Business Partner | D4: Independent / Network | E4: Known via EDII / Professional Network | F4: Multiple HRs – BFSI & IT | G4: Various | H4: WhatsApp / LinkedIn | J4: Pending | K4: No | M4: Key connector — can introduce us to senior HRs across sectors
A5: NTW-002 | B5: Furkan Sir | C5: Senior Advisor | D5: EDII / Network | E5: Internal EDII Referral | F5: Leena Lopez (Knowcraft) | G5: Knowcraft Analytics | H5: In-person | J5: Done | K5: Yes | L5: leenaantony@knowcraft.com | M5: Referred CHR-001. Can connect to more Ahmedabad HRs
A6: NTW-003 | B6: Rohan Shah | C6: Business Development / Network | D6: Professional Network | E6: Known via Industry Events | F6: Multiple HRs – Pharma & Mfg | G6: Various | H6: WhatsApp / Phone | J6: Active | K6: Partial | M6: Referred CHR-002, CHR-003, CHR-004. Follow up for more contacts
A7: NTW-004 | B7: Leena Lopez | C7: VP – Strategy & Human Resources | D7: Knowcraft Analytics | E7: Met via Furkan Sir (CHR-001) | F7: Rushad Shah (Cygnet.one) | G7: Cygnet.one | H7: Phone / LinkedIn | J7: Done | K7: Yes | L7: +91 9099048431 | M7: Referred CHR-005 (Rushad Shah). Strong HR network in IT sector
A8: NTW-005 | B8: Surya Verma | E8: Professional Network | J8: Not Started | K8: No
A9: NTW-006 | B9: Nikhil Trivedi | E9: Professional Network | J9: Not Started | K9: No
A10: NTW-007 | J10: Not Started | K10: No
A12: 🟢 Green = Done / Contact Received 🟡 Yellow = Active / In Progress 🟠 Orange = Pending ⬜ White = Not Started

Sheet MOM Repository
A1: Meeting Notes – MOM Repository
A2: Contact ID | B2: Meeting Date | C2: Detailed Minutes of Meeting | D2: Attachments (File / Link) | E2: Key Takeaways | F2: Action Items | G2: Owner | H2: Deadline
A3: CHR-001 | B3: 45672 | C3: Discussed campus hiring process for analytics roles. CHRO highlighted that current campus partners do not offer specialised analytics curriculum. EDII was proposed as a potential partner for a pilot batch. AI upskilling for existing employees was a secondary agenda item. | D3: MOM_001.pdf | E3: 1. EDII analytics program aligns with hiring needs 2. Pilot batch of 20 students proposed 3. AI upskilling budget available | F3: 1. Share EDII program brochure 2. Draft pilot MoU 3. Set up call with EDII placement team | G3: Vivek (EDII) | H3: 45689
A4: CHR-002 | B4: 45677 | C4: Detailed discussion on L&D spend utilization. Current training is ad-hoc; no competency framework. HR Head open to co-designing a structured framework with EDII. Budget of ₹50L available for FY26. | D4: MOM_002.pdf | E4: 1. ₹50L L&D budget unutilized 2. Mid-management is priority cohort 3. EDII can provide faculty support | F4: 1. Share L&D framework proposal 2. Identify 3 pilot cohort managers 3. Confirm faculty availability | G4: Vivek (EDII) | H4: 45693

Sheet Feedback Categorization
A1: Feedback Categorization
A2: Contact ID | B2: Company Name | C2: Feedback Category | D2: Feedback Details | E2: Priority | F2: Tags
A3: CHR-001 | B3: Infosys | C3: Skill Gaps | D3: Analytics and AI skills are scarce in fresh graduates. Most campus hires need 6-month reskilling before becoming productive. | E3: High | F3: Analytics, AI, Campus, Reskilling
A4: CHR-002 | B4: Tata Steel | C4: Skill Gaps | D4: Mid-management lacks people management and digital skills. No formal competency framework in place. | E4: High | F4: L&D, Mid-management, Competency
A5: CHR-003 | B5: HDFC Bank | C5: Budget Constraints | D5: L&D budget is primarily consumed by mandatory regulatory training. Little headroom for capability building. | E5: Medium | F5: BFSI, Compliance, Budget
A6: CHR-004 | B6: Bajaj Auto | C6: AI Adoption | D6: EV transition requires reskilling 3,000+ workers. Leadership is committed but union negotiations are ongoing. | E6: High | F6: EV, Reskilling, Automotive, Union
A7: CHR-005 | B7: Sun Pharma | C7: Hiring Challenges | D7: Niche pharma roles (regulatory affairs, QC) take 90+ days to fill. JD clarity and sourcing channels are gaps. | E7: Medium | F7: Pharma, Niche Hiring, TAT

Sheet Dashboard
A1: HR Outreach Dashboard
A3: Total Contacts | D3: Follow-ups Due Today or Overdue | G3: High-Interest Leads | J3: Converted Contacts
A4: =COUNTA('Contact Tracker'!A3:A1000) -> 19 | D4: =COUNTIFS('Contact Tracker'!T3:T1000,"<="&TODAY(),'Contact Tracker'!U3:U1000,"Pending") -> 12 | G4: =COUNTIF('Contact Tracker'!R3:R1000,"High") -> 11 | J4: =COUNTIF('Contact Tracker'!S3:S1000,"Converted") -> 0
A8: Industry | B8: Count | D8: Relationship Stage | E8: Count | G8: Feedback Category | H8: Count
A9: IT/Technology | B9: =COUNTIF('Contact Tracker'!G3:G1000,"IT/Technology") -> 0 | D9: New | E9: =COUNTIF('Contact Tracker'!S3:S1000,"New") -> 14 | G9: Hiring Challenges | H9: =COUNTIF('Feedback Categorization'!C3:C1000,"Hiring Challenges") -> 1
A10: Manufacturing | B10: =COUNTIF('Contact Tracker'!G3:G1000,"Manufacturing") -> 0 | D10: Engaged | E10: =COUNTIF('Contact Tracker'!S3:S1000,"Engaged") -> 0 | G10: Skill Gaps | H10: =COUNTIF('Feedback Categorization'!C3:C1000,"Skill Gaps") -> 2
A11: BFSI | B11: =COUNTIF('Contact Tracker'!G3:G1000,"BFSI") -> 0 | D11: Warm | E11: =COUNTIF('Contact Tracker'!S3:S1000,"Warm") -> 0 | G11: Campus Hiring | H11: =COUNTIF('Feedback Categorization'!C3:C1000,"Campus Hiring") -> 0
A12: Automotive | B12: =COUNTIF('Contact Tracker'!G3:G1000,"Automotive") -> 0 | D12: Converted | E12: =COUNTIF('Contact Tracker'!S3:S1000,"Converted") -> 0 | G12: AI Adoption | H12: =COUNTIF('Feedback Categorization'!C3:C1000,"AI Adoption") -> 1
A13: Pharma | B13: =COUNTIF('Contact Tracker'!G3:G1000,"Pharma") -> 0 | D13: Closed | E13: =COUNTIF('Contact Tracker'!S3:S1000,"Closed") -> 0 | G13: Budget Constraints | H13: =COUNTIF('Feedback Categorization'!C3:C1000,"Budget Constraints") -> 1
A14: FMCG | B14: =COUNTIF('Contact Tracker'!G3:G1000,"FMCG") -> 0 | G14: L&D Strategy | H14: =COUNTIF('Feedback Categorization'!C3:C1000,"L&D Strategy") -> 0
A15: Retail | B15: =COUNTIF('Contact Tracker'!G3:G1000,"Retail") -> 0 | G15: Attrition | H15: =COUNTIF('Feedback Categorization'!C3:C1000,"Attrition") -> 0
A16: Other | B16: =COUNTIF('Contact Tracker'!G3:G1000,"Other") -> 0 | G16: Other | H16: =COUNTIF('Feedback Categorization'!C3:C1000,"Other") -> 0
A54: 🟢 Green rows = High-Interest Lead | 🔴 Red rows = Overdue Follow-up | All charts auto-update when new data is added to Contact Tracker.

Sheet Targets to Networks
